Traceback (most recent call last):
  File "/home/vb17/util/p_mdrun", line 14, in <module>
Traceback (most recent call last):
  File "/home/vb17/util/p_mdrun", line 14, in <module>
    from mpi4py import MPI
ImportError: libmpi.so.1: cannot open shared object file: No such file or directory
Traceback (most recent call last):
  File "/home/vb17/util/p_mdrun", line 14, in <module>
    from mpi4py import MPI
ImportError: libmpi.so.1: cannot open shared object file: No such file or directory
Traceback (most recent call last):
  File "/home/vb17/util/p_mdrun", line 14, in <module>
    from mpi4py import MPI
Traceback (most recent call last):
  File "/home/vb17/util/p_mdrun", line 14, in <module>
    from mpi4py import MPI
ImportError: libmpi.so.1: cannot open shared object file: No such file or directory
Traceback (most recent call last):
  File "/home/vb17/util/p_mdrun", line 14, in <module>
    from mpi4py import MPI
ImportError: libmpi.so.1: cannot open shared object file: No such file or directory
Traceback (most recent call last):
  File "/home/vb17/util/p_mdrun", line 14, in <module>
    from mpi4py import MPI
ImportError: libmpi.so.1: cannot open shared object file: No such file or directory
Traceback (most recent call last):
  File "/home/vb17/util/p_mdrun", line 14, in <module>
    from mpi4py import MPI
Traceback (most recent call last):
  File "/home/vb17/util/p_mdrun", line 14, in <module>
Traceback (most recent call last):
  File "/home/vb17/util/p_mdrun", line 14, in <module>
Traceback (most recent call last):
  File "/home/vb17/util/p_mdrun", line 14, in <module>
    from mpi4py import MPI
ImportError: libmpi.so.1: cannot open shared object file: No such file or directory
ImportError: libmpi.so.1: cannot open shared object file: No such file or directory
ImportError: libmpi.so.1: cannot open shared object file: No such file or directory
Traceback (most recent call last):
  File "/home/vb17/util/p_mdrun", line 14, in <module>
    from mpi4py import MPI
ImportError: libmpi.so.1: cannot open shared object file: No such file or directory
    from mpi4py import MPI
ImportError: libmpi.so.1: cannot open shared object file: No such file or directory
    from mpi4py import MPI
ImportError: libmpi.so.1: cannot open shared object file: No such file or directory
Traceback (most recent call last):
  File "/home/vb17/util/p_mdrun", line 14, in <module>
    from mpi4py import MPI
ImportError: libmpi.so.1: cannot open shared object file: No such file or directory
Traceback (most recent call last):
  File "/home/vb17/util/p_mdrun", line 14, in <module>
Traceback (most recent call last):
  File "/home/vb17/util/p_mdrun", line 14, in <module>
Traceback (most recent call last):
  File "/home/vb17/util/p_mdrun", line 14, in <module>
Traceback (most recent call last):
  File "/home/vb17/util/p_mdrun", line 14, in <module>
Traceback (most recent call last):
  File "/home/vb17/util/p_mdrun", line 14, in <module>
    from mpi4py import MPI
ImportError: libmpi.so.1: cannot open shared object file: No such file or directory
Traceback (most recent call last):
  File "/home/vb17/util/p_mdrun", line 14, in <module>
Traceback (most recent call last):
  File "/home/vb17/util/p_mdrun", line 14, in <module>
    from mpi4py import MPI
    from mpi4py import MPI
ImportError: libmpi.so.1: cannot open shared object file: No such file or directory
    from mpi4py import MPI
ImportError: libmpi.so.1: cannot open shared object file: No such file or directory
    from mpi4py import MPI
ImportError: libmpi.so.1: cannot open shared object file: No such file or directory    from mpi4py import MPI
ImportError: libmpi.so.1: cannot open shared object file: No such file or directory
    from mpi4py import MPI
ImportError: libmpi.so.1: cannot open shared object file: No such file or directory
    from mpi4py import MPI
ImportError: libmpi.so.1: cannot open shared object file: No such file or directory

ImportError: libmpi.so.1: cannot open shared object file: No such file or directory
Traceback (most recent call last):
  File "/home/vb17/util/p_mdrun", line 14, in <module>
    from mpi4py import MPI
ImportError: libmpi.so.1: cannot open shared object file: No such file or directory
Traceback (most recent call last):
  File "/home/vb17/util/p_mdrun", line 14, in <module>
Traceback (most recent call last):
  File "/home/vb17/util/p_mdrun", line 14, in <module>
    from mpi4py import MPI
ImportError: libmpi.so.1: cannot open shared object file: No such file or directory
    from mpi4py import MPI
ImportError: libmpi.so.1: cannot open shared object file: No such file or directory
Traceback (most recent call last):
  File "/home/vb17/util/p_mdrun", line 14, in <module>
Traceback (most recent call last):
  File "/home/vb17/util/p_mdrun", line 14, in <module>
Traceback (most recent call last):
  File "/home/vb17/util/p_mdrun", line 14, in <module>
Traceback (most recent call last):
  File "/home/vb17/util/p_mdrun", line 14, in <module>
Traceback (most recent call last):
  File "/home/vb17/util/p_mdrun", line 14, in <module>
Traceback (most recent call last):
  File "/home/vb17/util/p_mdrun", line 14, in <module>
Traceback (most recent call last):
  File "/home/vb17/util/p_mdrun", line 14, in <module>
    from mpi4py import MPI
    from mpi4py import MPI
ImportError:     from mpi4py import MPI
ImportError: libmpi.so.1: cannot open shared object file: No such file or directory    from mpi4py import MPI
ImportError: libmpi.so.1: cannot open shared object file: No such file or directory
    from mpi4py import MPI
ImportError: libmpi.so.1: cannot open shared object file: No such file or directory
ImportError: libmpi.so.1: cannot open shared object file: No such file or directory
    from mpi4py import MPI
ImportError: libmpi.so.1: cannot open shared object file: No such file or directory
    from mpi4py import MPI
ImportError: libmpi.so.1: cannot open shared object file: No such file or directory
libmpi.so.1: cannot open shared object file: No such file or directory

Traceback (most recent call last):
  File "/home/vb17/util/p_mdrun", line 14, in <module>
    from mpi4py import MPI
ImportError: libmpi.so.1: cannot open shared object file: No such file or directory
Traceback (most recent call last):
  File "/home/vb17/util/p_mdrun", line 14, in <module>
    from mpi4py import MPI
ImportError: libmpi.so.1: cannot open shared object file: No such file or directory
Traceback (most recent call last):
  File "/home/vb17/util/p_mdrun", line 14, in <module>
Traceback (most recent call last):
  File "/home/vb17/util/p_mdrun", line 14, in <module>
Traceback (most recent call last):
  File "/home/vb17/util/p_mdrun", line 14, in <module>
Traceback (most recent call last):
  File "/home/vb17/util/p_mdrun", line 14, in <module>
Traceback (most recent call last):
  File "/home/vb17/util/p_mdrun", line 14, in <module>
Traceback (most recent call last):
  File "/home/vb17/util/p_mdrun", line 14, in <module>
Traceback (most recent call last):
  File "/home/vb17/util/p_mdrun", line 14, in <module>
Traceback (most recent call last):
  File "/home/vb17/util/p_mdrun", line 14, in <module>
Traceback (most recent call last):
  File "/home/vb17/util/p_mdrun", line 14, in <module>
Traceback (most recent call last):
  File "/home/vb17/util/p_mdrun", line 14, in <module>
Traceback (most recent call last):
  File "/home/vb17/util/p_mdrun", line 14, in <module>
Traceback (most recent call last):
  File "/home/vb17/util/p_mdrun", line 14, in <module>
Traceback (most recent call last):
  File "/home/vb17/util/p_mdrun", line 14, in <module>
Traceback (most recent call last):
  File "/home/vb17/util/p_mdrun", line 14, in <module>
Traceback (most recent call last):
  File "/home/vb17/util/p_mdrun", line 14, in <module>
Traceback (most recent call last):
  File "/home/vb17/util/p_mdrun", line 14, in <module>
Traceback (most recent call last):
  File "/home/vb17/util/p_mdrun", line 14, in <module>
Traceback (most recent call last):
  File "/home/vb17/util/p_mdrun", line 14, in <module>
Traceback (most recent call last):
  File "/home/vb17/util/p_mdrun", line 14, in <module>
Traceback (most recent call last):
  File "/home/vb17/util/p_mdrun", line 14, in <module>
Traceback (most recent call last):
  File "/home/vb17/util/p_mdrun", line 14, in <module>
Traceback (most recent call last):
  File "/home/vb17/util/p_mdrun", line 14, in <module>
Traceback (most recent call last):
  File "/home/vb17/util/p_mdrun", line 14, in <module>
Traceback (most recent call last):
  File "/home/vb17/util/p_mdrun", line 14, in <module>
Traceback (most recent call last):
  File "/home/vb17/util/p_mdrun", line 14, in <module>
Traceback (most recent call last):
  File "/home/vb17/util/p_mdrun", line 14, in <module>
Traceback (most recent call last):
  File "/home/vb17/util/p_mdrun", line 14, in <module>
Traceback (most recent call last):
  File "/home/vb17/util/p_mdrun", line 14, in <module>
Traceback (most recent call last):
  File "/home/vb17/util/p_mdrun", line 14, in <module>
Traceback (most recent call last):
  File "/home/vb17/util/p_mdrun", line 14, in <module>
Traceback (most recent call last):
  File "/home/vb17/util/p_mdrun", line 14, in <module>
Traceback (most recent call last):
  File "/home/vb17/util/p_mdrun", line 14, in <module>
    from mpi4py import MPI
ImportError: libmpi.so.1: cannot open shared object file: No such file or directory
    from mpi4py import MPI
ImportError: libmpi.so.1: cannot open shared object file: No such file or directory
    from mpi4py import MPI
ImportError: libmpi.so.1: cannot open shared object file: No such file or directory
    from mpi4py import MPI
ImportError: libmpi.so.1: cannot open shared object file: No such file or directory
    from mpi4py import MPI
ImportError: libmpi.so.1: cannot open shared object file: No such file or directory
    from mpi4py import MPI
ImportError: libmpi.so.1: cannot open shared object file: No such file or directory
    from mpi4py import MPI
ImportError: libmpi.so.1: cannot open shared object file: No such file or directory
    from mpi4py import MPI
ImportError: libmpi.so.1: cannot open shared object file: No such file or directory
    from mpi4py import MPI
ImportError: libmpi.so.1: cannot open shared object file: No such file or directory
    from mpi4py import MPI
ImportError: libmpi.so.1: cannot open shared object file: No such file or directory
    from mpi4py import MPI
ImportError: libmpi.so.1: cannot open shared object file: No such file or directory
    from mpi4py import MPI
ImportError: libmpi.so.1: cannot open shared object file: No such file or directory
    from mpi4py import MPI
ImportError: libmpi.so.1: cannot open shared object file: No such file or directory
    from mpi4py import MPI
ImportError: libmpi.so.1: cannot open shared object file: No such file or directory
    from mpi4py import MPI
ImportError: libmpi.so.1: cannot open shared object file: No such file or directory
    from mpi4py import MPI
ImportError: libmpi.so.1: cannot open shared object file: No such file or directory
    from mpi4py import MPI
ImportError: libmpi.so.1: cannot open shared object file: No such file or directory
    from mpi4py import MPI
ImportError: libmpi.so.1: cannot open shared object file: No such file or directory
    from mpi4py import MPI
ImportError: libmpi.so.1: cannot open shared object file: No such file or directory
    from mpi4py import MPI
ImportError: libmpi.so.1: cannot open shared object file: No such file or directory
    from mpi4py import MPI
ImportError: libmpi.so.1: cannot open shared object file: No such file or directory
    from mpi4py import MPI
ImportError: libmpi.so.1: cannot open shared object file: No such file or directory
    from mpi4py import MPI
ImportError: libmpi.so.1: cannot open shared object file: No such file or directory
    from mpi4py import MPI
ImportError: libmpi.so.1: cannot open shared object file: No such file or directory
    from mpi4py import MPI
ImportError: libmpi.so.1: cannot open shared object file: No such file or directory
    from mpi4py import MPI
ImportError: libmpi.so.1: cannot open shared object file: No such file or directory
    from mpi4py import MPI
ImportError: libmpi.so.1: cannot open shared object file: No such file or directory
    from mpi4py import MPI
ImportError: libmpi.so.1: cannot open shared object file: No such file or directory
    from mpi4py import MPI
ImportError: libmpi.so.1: cannot open shared object file: No such file or directory
    from mpi4py import MPI
ImportError: libmpi.so.1: cannot open shared object file: No such file or directory
    from mpi4py import MPI
ImportError: libmpi.so.1: cannot open shared object file: No such file or directory
    from mpi4py import MPI
ImportError: libmpi.so.1: cannot open shared object file: No such file or directory
